Workbook

Sheet Start Here
A1: Excel Portfolio Project — E-commerce Sales & Profitability Dashboard
A3: Goal: turn messy sales records into a clean, decision-ready dashboard that you can explain in an interview.
A5: Phase | B5: Priority | C5: Task | D5: Required output | E5: Skill | F5: Time box | G5: Status | H5: Evidence
A6: 1 | B6: TODAY | C6: Create Cleaned_Data from Raw_Sales; never overwrite Raw_Sales. | D6: One working copy/table | E6: Data discipline | F6: 10 min | G6: Done | H6: Sheet created
A7: 1 | B7: TODAY | C7: Remove exact duplicate orders. | D7: One row per Order_ID | E7: Duplicate handling | F7: 10 min | G7: Done | H7: Row count recorded
A8: 1 | B8: TODAY | C8: Standardize City and Payment_Mode; keep missing City as Unknown. | D8: Consistent labels | E8: Cleaning | F8: 20 min | G8: Done | H8: Before/after values
A9: 1 | B9: TODAY | C9: Use XLOOKUP to add Product_Name, Category, Unit_Price and Unit_Cost. | D9: Four lookup columns | E9: XLOOKUP | F9: 25 min | G9: Done | H9: Formula shown
A10: 1 | B10: TODAY | C10: Flag product codes missing from Product_Lookup; do not invent values. | D10: Data-quality flag | E10: Error handling | F10: 10 min | G10: Done | H10: Exception count
A11: 1 | B11: TODAY | C11: Calculate Gross_Revenue, Discount_Value, Net_Revenue, Cost and Profit. | D11: Five calculated columns | E11: Business formulas | F11: 25 min | G11: Done | H11: Formula checks
A12: 2 | B12: NEXT | C12: Add Profit_Margin, Delivery_Days, Month and Order_Band. | D12: Four analysis columns | E12: IF/date formulas | F12: 30 min | G12: Done | H12: Columns completed
A13: 2 | B13: NEXT | C13: Build PivotTables for month, city, category, channel and salesperson. | D13: Five PivotTables | E13: Pivot analysis | F13: 45 min | G13: Done | H13: Pivot sheet
A14: 2 | B14: NEXT | C14: Create KPIs: Net Revenue, Profit, Margin, Orders and Return Rate. | D14: Five KPI cards | E14: Aggregation | F14: 30 min | G14: Done | H14: Dashboard cards
A15: 3 | B15: NEXT | C15: Create 3–4 useful charts and exclude Grand Totals. | D15: Clean dashboard charts | E15: Chart design | F15: 45 min | G15: Done | H15: Dashboard
A16: 3 | B16: NEXT | C16: Write five findings and three business recommendations. | D16: Insight section | E16: Communication | F16: 30 min | G16: Done | H16: Findings
A17: 3 | B17: FINAL | C17: Quality check, README, screenshot and GitHub upload. | D17: Portfolio package | E17: Documentation/Git | F17: 45 min | G17: Not Started | H17: GitHub link
A20: TODAY'S FINISH LINE: complete tasks 1–6. Do not build the dashboard before the cleaned calculations are checked.
A22: Dataset note: this is a synthetic retail dataset created for learning. Present it as a portfolio project—not employment or client work.

Sheet Cleaned_data
A1: Order_ID | B1: Order_Date | C1: Ship_Date | D1: City | E1: Salesperson | F1: Product_Code | G1: Sales_Channel | H1: Customer_Segment | I1: Quantity | J1: Discount_Pct | K1: Payment_Mode | L1: Returned | M1: Customer_Rating | N1: Product_Name | O1: Category | P1: Unit_Price | Q1: Lookup_Status | R1: Unit_Cost | S1: Gross_Revenue | T1: Discount_Value | U1: Net_Revenue | V1: Cost | W1: Profit | X1: Profit_Margin | Y1: Delivery_Days | Z1: Month | AA1: Order_Band
A2: ORD-5001 | B2: 45792 | C2: 45794 | D2: Delhi | E2: Ananya | F2: P109 | G2: Corporate | H2: Small Business | I2: 2 | J2: 0 | K2: Cash on Delivery | L2: No | M2: 4 | N2: {=_xlfn.XLOOKUP(RawSalesTable5[[#This Row],[Product_Code]],ProductLookupTable[[#All],[Product_Code]],ProductLookupTable[[#All],[Product_Name]],"NOT FOUND")} -> Ergonomic Chair | O2: {=_xlfn.XLOOKUP(RawSalesTable5[[#This Row],[Product_Code]],ProductLookupTable[[#All],[Product_Code]],ProductLookupTable[[#All],[Category]],"NOT FOUND")} -> Furniture | P2: {=_xlfn.XLOOKUP(RawSalesTable5[[#This Row],[Product_Code]],ProductLookupTable[[#All],[Product_Code]],ProductLookupTable[[#All],[Unit_Price]],"NOT FOUND")} -> 10499 | Q2: =IF(COUNTIF(ProductLookupTable[Product_Code],RawSalesTable5[[#This Row],[Product_Code]])=0,"Missing Product","OK") -> OK | R2: {=_xlfn.XLOOKUP(RawSalesTable5[[#This Row],[Product_Code]],ProductLookupTable[[#All],[Product_Code]],ProductLookupTable[[#All],[Unit_Cost]],"NOT FOUND")} -> 7600 | S2: =IFERROR(RawSalesTable5[[#This Row],[Quantity]]*RawSalesTable5[[#This Row],[Unit_Price]],"NOT FOUND") -> 20998 | T2: =IFERROR(RawSalesTable5[[#This Row],[Gross_Revenue]]*RawSalesTable5[[#This Row],[Discount_Pct]],"NOT FOUND") -> 0 | U2: =IFERROR(RawSalesTable5[[#This Row],[Gross_Revenue]]-RawSalesTable5[[#This Row],[Discount_Value]],"NOT FOUND") -> 20998 | V2: =IFERROR(RawSalesTable5[[#This Row],[Quantity]]*RawSalesTable5[[#This Row],[Unit_Cost]],"NOT FOUND") -> 15200 | W2: =IFERROR(RawSalesTable5[[#This Row],[Net_Revenue]]-RawSalesTable5[[#This Row],[Cost]],"NOT FOUND") -> 5798 | X2: =IF(RawSalesTable5[[#This Row],[Lookup_Status]]="Missing Product","",IFERROR(RawSalesTable5[[#This Row],[Profit]]/RawSalesTable5[[#This Row],[Net_Revenue]],0)) -> 0.27612154 | Y2: =RawSalesTable5[[#This Row],[Ship_Date]]-RawSalesTable5[[#This Row],[Order_Date]] -> 2 | Z2: =DATE(YEAR(RawSalesTable5[[#This Row],[Order_Date]]),MONTH(RawSalesTable5[[#This Row],[Order_Date]]),1) -> 45778 | AA2: {=IF(RawSalesTable5[[#This Row],[Lookup_Status]]="Missing Product","",_xlfn.IFS(RawSalesTable5[[#This Row],[Net_Revenue]]>=20000,"High",RawSalesTable5[[#This Row],[Net_Revenue]]>=10000,"Medium",TRUE,"Low"))} -> High
A3: ORD-5002 | B3: 45985 | C3: 45987 | D3: Noida | E3: Rohan | F3: P106 | G3: Website | H3: Small Business | I3: 2 | J3: 0 | K3: Net Banking | L3: No | M3: 3 | N3: {=_xlfn.XLOOKUP(RawSalesTable5[[#This Row],[Product_Code]],ProductLookupTable[[#All],[Product_Code]],ProductLookupTable[[#All],[Product_Name]],"NOT FOUND")} -> Wireless Headset | O3: {=_xlfn.XLOOKUP(RawSalesTable5[[#This Row],[Product_Code]],ProductLookupTable[[#All],[Product_Code]],ProductLookupTable[[#All],[Category]],"NOT FOUND")} -> Audio | P3: {=_xlfn.XLOOKUP(RawSalesTable5[[#This Row],[Product_Code]],ProductLookupTable[[#All],[Product_Code]],ProductLookupTable[[#All],[Unit_Price]],"NOT FOUND")} -> 3499 | Q3: =IF(COUNTIF(ProductLookupTable[Product_Code],RawSalesTable5[[#This Row],[Product_Code]])=0,"Missing Product","OK") -> OK | R3: {=_xlfn.XLOOKUP(RawSalesTable5[[#This Row],[Product_Code]],ProductLookupTable[[#All],[Product_Code]],ProductLookupTable[[#All],[Unit_Cost]],"NOT FOUND")} -> 2100 | S3: =IFERROR(RawSalesTable5[[#This Row],[Quantity]]*RawSalesTable5[[#This Row],[Unit_Price]],"NOT FOUND") -> 6998 | T3: =IFERROR(RawSalesTable5[[#This Row],[Gross_Revenue]]*RawSalesTable5[[#This Row],[Discount_Pct]],"NOT FOUND") -> 0 | U3: =IFERROR(RawSalesTable5[[#This Row],[Gross_Revenue]]-RawSalesTable5[[#This Row],[Discount_Value]],"NOT FOUND") -> 6998 | V3: =IFERROR(RawSalesTable5[[#This Row],[Quantity]]*RawSalesTable5[[#This Row],[Unit_Cost]],"NOT FOUND") -> 4200 | W3: =IFERROR(RawSalesTable5[[#This Row],[Net_Revenue]]-RawSalesTable5[[#This Row],[Cost]],"NOT FOUND") -> 2798 | X3: =IF(RawSalesTable5[[#This Row],[Lookup_Status]]="Missing Product","",IFERROR(RawSalesTable5[[#This Row],[Profit]]/RawSalesTable5[[#This Row],[Net_Revenue]],0)) -> 0.39982852 | Y3: =RawSalesTable5[[#This Row],[Ship_Date]]-RawSalesTable5[[#This Row],[Order_Date]] -> 2 | Z3: =DATE(YEAR(RawSalesTable5[[#This Row],[Order_Date]]),MONTH(RawSalesTable5[[#This Row],[Order_Date]]),1) -> 45962 | AA3: {=IF(RawSalesTable5[[#This Row],[Lookup_Status]]="Missing Product","",_xlfn.IFS(RawSalesTable5[[#This Row],[Net_Revenue]]>=20000,"High",RawSalesTable5[[#This Row],[Net_Revenue]]>=10000,"Medium",TRUE,"Low"))} -> Low
A4: ORD-5003 | B4: 45782 | C4: 45783 | D4: Mathura | E4: Meera | F4: P106 | G4: Website | H4: Corporate | I4: 1 | J4: 0 | K4: Cash on Delivery | L4: No | M4: 3 | N4: {=_xlfn.XLOOKUP(RawSalesTable5[[#This Row],[Product_Code]],ProductLookupTable[[#All],[Product_Code]],ProductLookupTable[[#All],[Product_Name]],"NOT FOUND")} -> Wireless Headset | O4: {=_xlfn.XLOOKUP(RawSalesTable5[[#This Row],[Product_Code]],ProductLookupTable[[#All],[Product_Code]],ProductLookupTable[[#All],[Category]],"NOT FOUND")} -> Audio | P4: {=_xlfn.XLOOKUP(RawSalesTable5[[#This Row],[Product_Code]],ProductLookupTable[[#All],[Product_Code]],ProductLookupTable[[#All],[Unit_Price]],"NOT FOUND")} -> 3499 | Q4: =IF(COUNTIF(ProductLookupTable[Product_Code],RawSalesTable5[[#This Row],[Product_Code]])=0,"Missing Product","OK") -> OK | R4: {=_xlfn.XLOOKUP(RawSalesTable5[[#This Row],[Product_Code]],ProductLookupTable[[#All],[Product_Code]],ProductLookupTable[[#All],[Unit_Cost]],"NOT FOUND")} -> 2100 | S4: =IFERROR(RawSalesTable5[[#This Row],[Quantity]]*RawSalesTable5[[#This Row],[Unit_Price]],"NOT FOUND") -> 3499 | T4: =IFERROR(RawSalesTable5[[#This Row],[Gross_Revenue]]*RawSalesTable5[[#This Row],[Discount_Pct]],"NOT FOUND") -> 0 | U4: =IFERROR(RawSalesTable5[[#This Row],[Gross_Revenue]]-RawSalesTable5[[#This Row],[Discount_Value]],"NOT FOUND") -> 3499 | V4: =IFERROR(RawSalesTable5[[#This Row],[Quantity]]*RawSalesTable5[[#This Row],[Unit_Cost]],"NOT FOUND") -> 2100 | W4: =IFERROR(RawSalesTable5[[#This Row],[Net_Revenue]]-RawSalesTable5[[#This Row],[Cost]],"NOT FOUND") -> 1399 | X4: =IF(RawSalesTable5[[#This Row],[Lookup_Status]]="Missing Product","",IFERROR(RawSalesTable5[[#This Row],[Profit]]/RawSalesTable5[[#This Row],[Net_Revenue]],0)) -> 0.39982852 | Y4: =RawSalesTable5[[#This Row],[Ship_Date]]-RawSalesTable5[[#This Row],[Order_Date]] -> 1 | Z4: =DATE(YEAR(RawSalesTable5[[#This Row],[Order_Date]]),MONTH(RawSalesTable5[[#This Row],[Order_Date]]),1) -> 45778 | AA4: {=IF(RawSalesTable5[[#This Row],[Lookup_Status]]="Missing Product","",_xlfn.IFS(RawSalesTable5[[#This Row],[Net_Revenue]]>=20000,"High",RawSalesTable5[[#This Row],[Net_Revenue]]>=10000,"Medium",TRUE,"Low"))} -> Low
A5: ORD-5004 | B5: 45851 | C5: 45858 | D5: Gurugram | E5: Vikram | F5: P108 | G5: Corporate | H5: Consumer | I5: 2 | J5: 0.05 | K5: Cash on Delivery | L5: No | M5: 4 | N5: {=_xlfn.XLOOKUP(RawSalesTable5[[#This Row],[Product_Code]],ProductLookupTable[[#All],[Product_Code]],ProductLookupTable[[#All],[Product_Name]],"NOT FOUND")} -> SSD 1TB | O5: {=_xlfn.XLOOKUP(RawSalesTable5[[#This Row],[Product_Code]],ProductLookupTable[[#All],[Product_Code]],ProductLookupTable[[#All],[Category]],"NOT FOUND")} -> Storage | P5: {=_xlfn.XLOOKUP(RawSalesTable5[[#This Row],[Product_Code]],ProductLookupTable[[#All],[Product_Code]],ProductLookupTable[[#All],[Unit_Price]],"NOT FOUND")} -> 6999 | Q5: =IF(COUNTIF(ProductLookupTable[Product_Code],RawSalesTable5[[#This Row],[Product_Code]])=0,"Missing Product","OK") -> OK | R5: {=_xlfn.XLOOKUP(RawSalesTable5[[#This Row],[Product_Code]],ProductLookupTable[[#All],[Product_Code]],ProductLookupTable[[#All],[Unit_Cost]],"NOT FOUND")} -> 4900 | S5: =IFERROR(RawSalesTable5[[#This Row],[Quantity]]*RawSalesTable5[[#This Row],[Unit_Price]],"NOT FOUND") -> 13998 | T5: =IFERROR(RawSalesTable5[[#This Row],[Gross_Revenue]]*RawSalesTable5[[#This Row],[Discount_Pct]],"NOT FOUND") -> 699.9 | U5: =IFERROR(RawSalesTable5[[#This Row],[Gross_Revenue]]-RawSalesTable5[[#This Row],[Discount_Value]],"NOT FOUND") -> 13298.1 | V5: =IFERROR(RawSalesTable5[[#This Row],[Quantity]]*RawSalesTable5[[#This Row],[Unit_Cost]],"NOT FOUND") -> 9800 | W5: =IFERROR(RawSalesTable5[[#This Row],[Net_Revenue]]-RawSalesTable5[[#This Row],[Cost]],"NOT FOUND") -> 3498.1 | X5: =IF(RawSalesTable5[[#This Row],[Lookup_Status]]="Missing Product","",IFERROR(RawSalesTable5[[#This Row],[Profit]]/RawSalesTable5[[#This Row],[Net_Revenue]],0)) -> 0.26305262 | Y5: =RawSalesTable5[[#This Row],[Ship_Date]]-RawSalesTable5[[#This Row],[Order_Date]] -> 7 | Z5: =DATE(YEAR(RawSalesTable5[[#This Row],[Order_Date]]),MONTH(RawSalesTable5[[#This Row],[Order_Date]]),1) -> 45839 | AA5: {=IF(RawSalesTable5[[#This Row],[Lookup_Status]]="Missing Product","",_xlfn.IFS(RawSalesTable5[[#This Row],[Net_Revenue]]>=20000,"High",RawSalesTable5[[#This Row],[Net_Revenue]]>=10000,"Medium",TRUE,"Low"))} -> Medium
A6: ORD-5005 | B6: 45838 | C6: 45843 | D6: Faridabad | E6: Sana | F6: P111 | G6: Marketplace | H6: Consumer | I6: 1 | J6: 0.2 | K6: Net Banking | L6: No | M6: 5 | N6: {=_xlfn.XLOOKUP(RawSalesTable5[[#This Row],[Product_Code]],ProductLookupTable[[#All],[Product_Code]],ProductLookupTable[[#All],[Product_Name]],"NOT FOUND")} -> Bluetooth Speaker | O6: {=_xlfn.XLOOKUP(RawSalesTable5[[#This Row],[Product_Code]],ProductLookupTable[[#All],[Product_Code]],ProductLookupTable[[#All],[Category]],"NOT FOUND")} -> Audio | P6: {=_xlfn.XLOOKUP(RawSalesTable5[[#This Row],[Product_Code]],ProductLookupTable[[#All],[Product_Code]],ProductLookupTable[[#All],[Unit_Price]],"NOT FOUND")} -> 2799 | Q6: =IF(COUNTIF(ProductLookupTable[Product_Code],RawSalesTable5[[#This Row],[Product_Code]])=0,"Missing Product","OK") -> OK | R6: {=_xlfn.XLOOKUP(RawSalesTable5[[#This Row],[Product_Code]],ProductLookupTable[[#All],[Product_Code]],ProductLookupTable[[#All],[Unit_Cost]],"NOT FOUND")} -> 1650 | S6: =IFERROR(RawSalesTable5[[#This Row],[Quantity]]*RawSalesTable5[[#This Row],[Unit_Price]],"NOT FOUND") -> 2799 | T6: =IFERROR(RawSalesTable5[[#This Row],[Gross_Revenue]]*RawSalesTable5[[#This Row],[Discount_Pct]],"NOT FOUND") -> 559.8 | U6: =IFERROR(RawSalesTable5[[#This Row],[Gross_Revenue]]-RawSalesTable5[[#This Row],[Discount_Value]],"NOT FOUND") -> 2239.2 | V6: =IFERROR(RawSalesTable5[[#This Row],[Quantity]]*RawSalesTable5[[#This Row],[Unit_Cost]],"NOT FOUND") -> 1650 | W6: =IFERROR(RawSalesTable5[[#This Row],[Net_Revenue]]-RawSalesTable5[[#This Row],[Cost]],"NOT FOUND") -> 589.2 | X6: =IF(RawSalesTable5[[#This Row],[Lookup_Status]]="Missing Product","",IFERROR(RawSalesTable5[[#This Row],[Profit]]/RawSalesTable5[[#This Row],[Net_Revenue]],0)) -> 0.26312969 | Y6: =RawSalesTable5[[#This Row],[Ship_Date]]-RawSalesTable5[[#This Row],[Order_Date]] -> 5 | Z6: =DATE(YEAR(RawSalesTable5[[#This Row],[Order_Date]]),MONTH(RawSalesTable5[[#This Row],[Order_Date]]),1) -> 45809 | AA6: {=IF(RawSalesTable5[[#This Row],[Lookup_Status]]="Missing Product","",_xlfn.IFS(RawSalesTable5[[#This Row],[Net_Revenue]]>=20000,"High",RawSalesTable5[[#This Row],[Net_Revenue]]>=10000,"Medium",TRUE,"Low"))} -> Low
A7: ORD-5006 | B7: 45964 | C7: 45972 | D7: Delhi | E7: Arjun | F7: P106 | G7: Website | H7: Small Business | I7: 4 | J7: 0.1 | K7: Credit Card | L7: No | M7: 4 | N7: {=_xlfn.XLOOKUP(RawSalesTable5[[#This Row],[Product_Code]],ProductLookupTable[[#All],[Product_Code]],ProductLookupTable[[#All],[Product_Name]],"NOT FOUND")} -> Wireless Headset | O7: {=_xlfn.XLOOKUP(RawSalesTable5[[#This Row],[Product_Code]],ProductLookupTable[[#All],[Product_Code]],ProductLookupTable[[#All],[Category]],"NOT FOUND")} -> Audio | P7: {=_xlfn.XLOOKUP(RawSalesTable5[[#This Row],[Product_Code]],ProductLookupTable[[#All],[Product_Code]],ProductLookupTable[[#All],[Unit_Price]],"NOT FOUND")} -> 3499 | Q7: =IF(COUNTIF(ProductLookupTable[Product_Code],RawSalesTable5[[#This Row],[Product_Code]])=0,"Missing Product","OK") -> OK | R7: {=_xlfn.XLOOKUP(RawSalesTable5[[#This Row],[Product_Code]],ProductLookupTable[[#All],[Product_Code]],ProductLookupTable[[#All],[Unit_Cost]],"NOT FOUND")} -> 2100 | S7: =IFERROR(RawSalesTable5[[#This Row],[Quantity]]*RawSalesTable5[[#This Row],[Unit_Price]],"NOT FOUND") -> 13996 | T7: =IFERROR(RawSalesTable5[[#This Row],[Gross_Revenue]]*RawSalesTable5[[#This Row],[Discount_Pct]],"NOT FOUND") -> 1399.6 | U7: =IFERROR(RawSalesTable5[[#This Row],[Gross_Revenue]]-RawSalesTable5[[#This Row],[Discount_Value]],"NOT FOUND") -> 12596.4 | V7: =IFERROR(RawSalesTable5[[#This Row],[Quantity]]*RawSalesTable5[[#This Row],[Unit_Cost]],"NOT FOUND") -> 8400 | W7: =IFERROR(RawSalesTable5[[#This Row],[Net_Revenue]]-RawSalesTable5[[#This Row],[Cost]],"NOT FOUND") -> 4196.4 | X7: =IF(RawSalesTable5[[#This Row],[Lookup_Status]]="Missing Product","",IFERROR(RawSalesTable5[[#This Row],[Profit]]/RawSalesTable5[[#This Row],[Net_Revenue]],0)) -> 0.3331428 | Y7: =RawSalesTable5[[#This Row],[Ship_Date]]-RawSalesTable5[[#This Row],[Order_Date]] -> 8 | Z7: =DATE(YEAR(RawSalesTable5[[#This Row],[Order_Date]]),MONTH(RawSalesTable5[[#This Row],[Order_Date]]),1) -> 45962 | AA7: {=IF(RawSalesTable5[[#This Row],[Lookup_Status]]="Missing Product","",_xlfn.IFS(RawSalesTable5[[#This Row],[Net_Revenue]]>=20000,"High",RawSalesTable5[[#This Row],[Net_Revenue]]>=10000,"Medium",TRUE,"Low"))} -> Medium
A8: ORD-5007 | B8: 45812 | C8: 45816 | D8: Noida | E8: Ananya | F8: P104 | G8: Corporate | H8: Consumer | I8: 5 | J8: 0 | K8: Credit Card | L8: No | M8: 3 | N8: {=_xlfn.XLOOKUP(RawSalesTable5[[#This Row],[Product_Code]],ProductLookupTable[[#All],[Product_Code]],ProductLookupTable[[#All],[Product_Name]],"NOT FOUND")} -> USB-C Hub | O8: {=_xlfn.XLOOKUP(RawSalesTable5[[#This Row],[Product_Code]],ProductLookupTable[[#All],[Product_Code]],ProductLookupTable[[#All],[Category]],"NOT FOUND")} -> Accessories | P8: {=_xlfn.XLOOKUP(RawSalesTable5[[#This Row],[Product_Code]],ProductLookupTable[[#All],[Product_Code]],ProductLookupTable[[#All],[Unit_Price]],"NOT FOUND")} -> 1599 | Q8: =IF(COUNTIF(ProductLookupTable[Product_Code],RawSalesTable5[[#This Row],[Product_Code]])=0,"Missing Product","OK") -> OK | R8: {=_xlfn.XLOOKUP(RawSalesTable5[[#This Row],[Product_Code]],ProductLookupTable[[#All],[Product_Code]],ProductLookupTable[[#All],[Unit_Cost]],"NOT FOUND")} -> 870 | S8: =IFERROR(RawSalesTable5[[#This Row],[Quantity]]*RawSalesTable5[[#This Row],[Unit_Price]],"NOT FOUND") -> 7995 | T8: =IFERROR(RawSalesTable5[[#This Row],[Gross_Revenue]]*RawSalesTable5[[#This Row],[Discount_Pct]],"NOT FOUND") -> 0 | U8: =IFERROR(RawSalesTable5[[#This Row],[Gross_Revenue]]-RawSalesTable5[[#This Row],[Discount_Value]],"NOT FOUND") -> 7995 | V8: =IFERROR(RawSalesTable5[[#This Row],[Quantity]]*RawSalesTable5[[#This Row],[Unit_Cost]],"NOT FOUND") -> 4350 | W8: =IFERROR(RawSalesTable5[[#This Row],[Net_Revenue]]-RawSalesTable5[[#This Row],[Cost]],"NOT FOUND") -> 3645 | X8: =IF(RawSalesTable5[[#This Row],[Lookup_Status]]="Missing Product","",IFERROR(RawSalesTable5[[#This Row],[Profit]]/RawSalesTable5[[#This Row],[Net_Revenue]],0)) -> 0.45590994 | Y8: =RawSalesTable5[[#This Row],[Ship_Date]]-RawSalesTable5[[#This Row],[Order_Date]] -> 4 | Z8: =DATE(YEAR(RawSalesTable5[[#This Row],[Order_Date]]),MONTH(RawSalesTable5[[#This Row],[Order_Date]]),1) -> 45809 | AA8: {=IF(RawSalesTable5[[#This Row],[Lookup_Status]]="Missing Product","",_xlfn.IFS(RawSalesTable5[[#This Row],[Net_Revenue]]>=20000,"High",RawSalesTable5[[#This Row],[Net_Revenue]]>=10000,"Medium",TRUE,"Low"))} -> Low
A9: ORD-5008 | B9: 46020 | C9: 46024 | D9: Mathura | E9: Rohan | F9: P102 | G9: Marketplace | H9: Corporate | I9: 5 | J9: 0 | K9: Debit Card | L9: No | M9: 5 | N9: {=_xlfn.XLOOKUP(RawSalesTable5[[#This Row],[Product_Code]],ProductLookupTable[[#All],[Product_Code]],ProductLookupTable[[#All],[Product_Name]],"NOT FOUND")} -> Mechanical Keyboard | O9: {=_xlfn.XLOOKUP(RawSalesTable5[[#This Row],[Product_Code]],ProductLookupTable[[#All],[Product_Code]],ProductLookupTable[[#All],[Category]],"NOT FOUND")} -> Accessories | P9: {=_xlfn.XLOOKUP(RawSalesTable5[[#This Row],[Product_Code]],ProductLookupTable[[#All],[Product_Code]],ProductLookupTable[[#All],[Unit_Price]],"NOT FOUND")} -> 2499 | Q9: =IF(COUNTIF(ProductLookupTable[Product_Code],RawSalesTable5[[#This Row],[Product_Code]])=0,"Missing Product","OK") -> OK | R9: {=_xlfn.XLOOKUP(RawSalesTable5[[#This Row],[Product_Code]],ProductLookupTable[[#All],[Product_Code]],ProductLookupTable[[#All],[Unit_Cost]],"NOT FOUND")} -> 1450 | S9: =IFERROR(RawSalesTable5[[#This Row],[Quantity]]*RawSalesTable5[[#This Row],[Unit_Price]],"NOT FOUND") -> 12495 | T9: =IFERROR(RawSalesTable5[[#This Row],[Gross_Revenue]]*RawSalesTable5[[#This Row],[Discount_Pct]],"NOT FOUND") -> 0 | U9: =IFERROR(RawSalesTable5[[#This Row],[Gross_Revenue]]-RawSalesTable5[[#This Row],[Discount_Value]],"NOT FOUND") -> 12495 | V9: =IFERROR(RawSalesTable5[[#This Row],[Quantity]]*RawSalesTable5[[#This Row],[Unit_Cost]],"NOT FOUND") -> 7250 | W9: =IFERROR(RawSalesTable5[[#This Row],[Net_Revenue]]-RawSalesTable5[[#This Row],[Cost]],"NOT FOUND") -> 5245 | X9: =IF(RawSalesTable5[[#This Row],[Lookup_Status]]="Missing Product","",IFERROR(RawSalesTable5[[#This Row],[Profit]]/RawSalesTable5[[#This Row],[Net_Revenue]],0)) -> 0.41976791 | Y9: =RawSalesTable5[[#This Row],[Ship_Date]]-RawSalesTable5[[#This Row],[Order_Date]] -> 4 | Z9: =DATE(YEAR(RawSalesTable5[[#This Row],[Order_Date]]),MONTH(RawSalesTable5[[#This Row],[Order_Date]]),1) -> 45992 | AA9: {=IF(RawSalesTable5[[#This Row],[Lookup_Status]]="Missing Product","",_xlfn.IFS(RawSalesTable5[[#This Row],[Net_Revenue]]>=20000,"High",RawSalesTable5[[#This Row],[Net_Revenue]]>=10000,"Medium",TRUE,"Low"))} -> Medium
A10: ORD-5009 | B10: 45829 | C10: 45832 | D10: Gurugram | E10: Meera | F10: P103 | G10: Marketplace | H10: Small Business | I10: 3 | J10: 0.1 | K10: Credit Card | L10: No | M10: 4 | N10: {=_xlfn.XLOOKUP(RawSalesTable5[[#This Row],[Product_Code]],ProductLookupTable[[#All],[Product_Code]],ProductLookupTable[[#All],[Product_Name]],"NOT FOUND")} -> HD Webcam | O10: {=_xlfn.XLOOKUP(RawSalesTable5[[#This Row],[Product_Code]],ProductLookupTable[[#All],[Product_Code]],ProductLookupTable[[#All],[Category]],"NOT FOUND")} -> Accessories | P10: {=_xlfn.XLOOKUP(RawSalesTable5[[#This Row],[Product_Code]],ProductLookupTable[[#All],[Product_Code]],ProductLookupTable[[#All],[Unit_Price]],"NOT FOUND")} -> 2899 | Q10: =IF(COUNTIF(ProductLookupTable[Product_Code],RawSalesTable5[[#This Row],[Product_Code]])=0,"Missing Product","OK") -> OK | R10: {=_xlfn.XLOOKUP(RawSalesTable5[[#This Row],[Product_Code]],ProductLookupTable[[#All],[Product_Code]],ProductLookupTable[[#All],[Unit_Cost]],"NOT FOUND")} -> 1700 | S10: =IFERROR(RawSalesTable5[[#This Row],[Quantity]]*RawSalesTable5[[#This Row],[Unit_Price]],"NOT FOUND") -> 8697 | T10: =IFERROR(RawSalesTable5[[#This Row],[Gross_Revenue]]*RawSalesTable5[[#This Row],[Discount_Pct]],"NOT FOUND") -> 869.7 | U10: =IFERROR(RawSalesTable5[[#This Row],[Gross_Revenue]]-RawSalesTable5[[#This Row],[Discount_Value]],"NOT FOUND") -> 7827.3 | V10: =IFERROR(RawSalesTable5[[#This Row],[Quantity]]*RawSalesTable5[[#This Row],[Unit_Cost]],"NOT FOUND") -> 5100 | W10: =IFERROR(RawSalesTable5[[#This Row],[Net_Revenue]]-RawSalesTable5[[#This Row],[Cost]],"NOT FOUND") -> 2727.3 | X10: =IF(RawSalesTable5[[#This Row],[Lookup_Status]]="Missing Product","",IFERROR(RawSalesTable5[[#This Row],[Profit]]/RawSalesTable5[[#This Row],[Net_Revenue]],0)) -> 0.34843433 | Y10: =RawSalesTable5[[#This Row],[Ship_Date]]-RawSalesTable5[[#This Row],[Order_Date]] -> 3 | Z10: =DATE(YEAR(RawSalesTable5[[#This Row],[Order_Date]]),MONTH(RawSalesTable5[[#This Row],[Order_Date]]),1) -> 45809 | AA10: {=IF(RawSalesTable5[[#This Row],[Lookup_Status]]="Missing Product","",_xlfn.IFS(RawSalesTable5[[#This Row],[Net_Revenue]]>=20000,"High",RawSalesTable5[[#This Row],[Net_Revenue]]>=10000,"Medium",TRUE,"Low"))} -> Low
A11: ORD-5010 | B11: 45778 | C11: 45786 | D11: Faridabad | E11: Vikram | F11: P101 | G11: Retail Store | H11: Small Business | I11: 3 | J11: 0.2 | K11: Credit Card | L11: Yes | M11: 1 | N11: {=_xlfn.XLOOKUP(RawSalesTable5[[#This Row],[Product_Code]],ProductLookupTable[[#All],[Product_Code]],ProductLookupTable[[#All],[Product_Name]],"NOT FOUND")} -> Wireless Mouse | O11: {=_xlfn.XLOOKUP(RawSalesTable5[[#This Row],[Product_Code]],ProductLookupTable[[#All],[Product_Code]],ProductLookupTable[[#All],[Category]],"NOT FOUND")} -> Accessories | P11: {=_xlfn.XLOOKUP(RawSalesTable5[[#This Row],[Product_Code]],ProductLookupTable[[#All],[Product_Code]],ProductLookupTable[[#All],[Unit_Price]],"NOT FOUND")} -> 799 | Q11: =IF(COUNTIF(ProductLookupTable[Product_Code],RawSalesTable5[[#This Row],[Product_Code]])=0,"Missing Product","OK") -> OK | R11: {=_xlfn.XLOOKUP(RawSalesTable5[[#This Row],[Product_Code]],ProductLookupTable[[#All],[Product_Code]],ProductLookupTable[[#All],[Unit_Cost]],"NOT FOUND")} -> 420 | S11: =IFERROR(RawSalesTable5[[#This Row],[Quantity]]*RawSalesTable5[[#This Row],[Unit_Price]],"NOT FOUND") -> 2397 | T11: =IFERROR(RawSalesTable5[[#This Row],[Gross_Revenue]]*RawSalesTable5[[#This Row],[Discount_Pct]],"NOT FOUND") -> 479.4 | U11: =IFERROR(RawSalesTable5[[#This Row],[Gross_Revenue]]-RawSalesTable5[[#This Row],[Discount_Value]],"NOT FOUND") -> 1917.6 | V11: =IFERROR(RawSalesTable5[[#This Row],[Quantity]]*RawSalesTable5[[#This Row],[Unit_Cost]],"NOT FOUND") -> 1260 | W11: =IFERROR(RawSalesTable5[[#This Row],[Net_Revenue]]-RawSalesTable5[[#This Row],[Cost]],"NOT FOUND") -> 657.6 | X11: =IF(RawSalesTable5[[#This Row],[Lookup_Status]]="Missing Product","",IFERROR(RawSalesTable5[[#This Row],[Profit]]/RawSalesTable5[[#This Row],[Net_Revenue]],0)) -> 0.34292866 | Y11: =RawSalesTable5[[#This Row],[Ship_Date]]-RawSalesTable5[[#This Row],[Order_Date]] -> 8 | Z11: =DATE(YEAR(RawSalesTable5[[#This Row],[Order_Date]]),MONTH(RawSalesTable5[[#This Row],[Order_Date]]),1) -> 45778 | AA11: {=IF(RawSalesTable5[[#This Row],[Lookup_Status]]="Missing Product","",_xlfn.IFS(RawSalesTable5[[#This Row],[Net_Revenue]]>=20000,"High",RawSalesTable5[[#This Row],[Net_Revenue]]>=10000,"Medium",TRUE,"Low"))} -> Low
A12: ORD-5011 | B12: 45695 | C12: 45699 | D12: Delhi | E12: Sana | F12: P104 | G12: Website | H12: Small Business | I12: 2 | J12: 0.1 | K12: Credit Card | L12: No | M12: 5 | N12: {=_xlfn.XLOOKUP(RawSalesTable5[[#This Row],[Product_Code]],ProductLookupTable[[#All],[Product_Code]],ProductLookupTable[[#All],[Product_Name]],"NOT FOUND")} -> USB-C Hub | O12: {=_xlfn.XLOOKUP(RawSalesTable5[[#This Row],[Product_Code]],ProductLookupTable[[#All],[Product_Code]],ProductLookupTable[[#All],[Category]],"NOT FOUND")} -> Accessories | P12: {=_xlfn.XLOOKUP(RawSalesTable5[[#This Row],[Product_Code]],ProductLookupTable[[#All],[Product_Code]],ProductLookupTable[[#All],[Unit_Price]],"NOT FOUND")} -> 1599 | Q12: =IF(COUNTIF(ProductLookupTable[Product_Code],RawSalesTable5[[#This Row],[Product_Code]])=0,"Missing Product","OK") -> OK | R12: {=_xlfn.XLOOKUP(RawSalesTable5[[#This Row],[Product_Code]],ProductLookupTable[[#All],[Product_Code]],ProductLookupTable[[#All],[Unit_Cost]],"NOT FOUND")} -> 870 | S12: =IFERROR(RawSalesTable5[[#This Row],[Quantity]]*RawSalesTable5[[#This Row],[Unit_Price]],"NOT FOUND") -> 3198 | T12: =IFERROR(RawSalesTable5[[#This Row],[Gross_Revenue]]*RawSalesTable5[[#This Row],[Discount_Pct]],"NOT FOUND") -> 319.8 | U12: =IFERROR(RawSalesTable5[[#This Row],[Gross_Revenue]]-RawSalesTable5[[#This Row],[Discount_Value]],"NOT FOUND") -> 2878.2 | V12: =IFERROR(RawSalesTable5[[#This Row],[Quantity]]*RawSalesTable5[[#This Row],[Unit_Cost]],"NOT FOUND") -> 1740 | W12: =IFERROR(RawSalesTable5[[#This Row],[Net_Revenue]]-RawSalesTable5[[#This Row],[Cost]],"NOT FOUND") -> 1138.2 | X12: =IF(RawSalesTable5[[#This Row],[Lookup_Status]]="Missing Product","",IFERROR(RawSalesTable5[[#This Row],[Profit]]/RawSalesTable5[[#This Row],[Net_Revenue]],0)) -> 0.39545549 | Y12: =RawSalesTable5[[#This Row],[Ship_Date]]-RawSalesTable5[[#This Row],[Order_Date]] -> 4 | Z12: =DATE(YEAR(RawSalesTable5[[#This Row],[Order_Date]]),MONTH(RawSalesTable5[[#This Row],[Order_Date]]),1) -> 45689 | AA12: {=IF(RawSalesTable5[[#This Row],[Lookup_Status]]="Missing Product","",_xlfn.IFS(RawSalesTable5[[#This Row],[Net_Revenue]]>=20000,"High",RawSalesTable5[[#This Row],[Net_Revenue]]>=10000,"Medium",TRUE,"Low"))} -> Low
A13: ORD-5012 | B13: 46006 | C13: 46014 | D13: Noida | E13: Arjun | F13: P102 | G13: Corporate | H13: Consumer | I13: 5 | J13: 0.1 | K13: Cash on Delivery | L13: No | M13: 5 | N13: {=_xlfn.XLOOKUP(RawSalesTable5[[#This Row],[Product_Code]],ProductLookupTable[[#All],[Product_Code]],ProductLookupTable[[#All],[Product_Name]],"NOT FOUND")} -> Mechanical Keyboard | O13: {=_xlfn.XLOOKUP(RawSalesTable5[[#This Row],[Product_Code]],ProductLookupTable[[#All],[Product_Code]],ProductLookupTable[[#All],[Category]],"NOT FOUND")} -> Accessories | P13: {=_xlfn.XLOOKUP(RawSalesTable5[[#This Row],[Product_Code]],ProductLookupTable[[#All],[Product_Code]],ProductLookupTable[[#All],[Unit_Price]],"NOT FOUND")} -> 2499 | Q13: =IF(COUNTIF(ProductLookupTable[Product_Code],RawSalesTable5[[#This Row],[Product_Code]])=0,"Missing Product","OK") -> OK | R13: {=_xlfn.XLOOKUP(RawSalesTable5[[#This Row],[Product_Code]],ProductLookupTable[[#All],[Product_Code]],ProductLookupTable[[#All],[Unit_Cost]],"NOT FOUND")} -> 1450 | S13: =IFERROR(RawSalesTable5[[#This Row],[Quantity]]*RawSalesTable5[[#This Row],[Unit_Price]],"NOT FOUND") -> 12495 | T13: =IFERROR(RawSalesTable5[[#This Row],[Gross_Revenue]]*RawSalesTable5[[#This Row],[Discount_Pct]],"NOT FOUND") -> 1249.5 | U13: =IFERROR(RawSalesTable5[[#This Row],[Gross_Revenue]]-RawSalesTable5[[#This Row],[Discount_Value]],"NOT FOUND") -> 11245.5 | V13: =IFERROR(RawSalesTable5[[#This Row],[Quantity]]*RawSalesTable5[[#This Row],[Unit_Cost]],"NOT FOUND") -> 7250 | W13: =IFERROR(RawSalesTable5[[#This Row],[Net_Revenue]]-RawSalesTable5[[#This Row],[Cost]],"NOT FOUND") -> 3995.5 | X13: =IF(RawSalesTable5[[#This Row],[Lookup_Status]]="Missing Product","",IFERROR(RawSalesTable5[[#This Row],[Profit]]/RawSalesTable5[[#This Row],[Net_Revenue]],0)) -> 0.35529767 | Y13: =RawSalesTable5[[#This Row],[Ship_Date]]-RawSalesTable5[[#This Row],[Order_Date]] -> 8 | Z13: =DATE(YEAR(RawSalesTable5[[#This Row],[Order_Date]]),MONTH(RawSalesTable5[[#This Row],[Order_Date]]),1) -> 45992 | AA13: {=IF(RawSalesTable5[[#This Row],[Lookup_Status]]="Missing Product","",_xlfn.IFS(RawSalesTable5[[#This Row],[Net_Revenue]]>=20000,"High",RawSalesTable5[[#This Row],[Net_Revenue]]>=10000,"Medium",TRUE,"Low"))} -> Medium
... A361: ORD-5360 | B361: 45877 | C361: 45880 | D361: Faridabad | E361: Arjun | F361: P108 | G361: Retail Store | H361: Corporate | I361: 3 | J361: 0.15 | K361: UPI | L361: No | M361: 3 | N361: {=_xlfn.XLOOKUP(RawSalesTable5[[#This Row],[Product_Code]],ProductLookupTable[[#All],[Product_Code]],ProductLookupTable[[#All],[Product_Name]],"NOT FOUND")} -> SSD 1TB | O361: {=_xlfn.XLOOKUP(RawSalesTable5[[#This Row],[Product_Code]],ProductLookupTable[[#All],[Product_Code]],ProductLookupTable[[#All],[Category]],"NOT FOUND")} -> Storage | P361: {=_xlfn.XLOOKUP(RawSalesTable5[[#This Row],[Product_Code]],ProductLookupTable[[#All],[Product_Code]],ProductLookupTable[[#All],[Unit_Price]],"NOT FOUND")} -> 6999 | Q361: =IF(COUNTIF(ProductLookupTable[Product_Code],RawSalesTable5[[#This Row],[Product_Code]])=0,"Missing Product","OK") -> OK | R361: {=_xlfn.XLOOKUP(RawSalesTable5[[#This Row],[Product_Code]],ProductLookupTable[[#All],[Product_Code]],ProductLookupTable[[#All],[Unit_Cost]],"NOT FOUND")} -> 4900 | S361: =IFERROR(RawSalesTable5[[#This Row],[Quantity]]*RawSalesTable5[[#This Row],[Unit_Price]],"NOT FOUND") -> 20997 | T361: =IFERROR(RawSalesTable5[[#This Row],[Gross_Revenue]]*RawSalesTable5[[#This Row],[Discount_Pct]],"NOT FOUND") -> 3149.55 | U361: =IFERROR(RawSalesTable5[[#This Row],[Gross_Revenue]]-RawSalesTable5[[#This Row],[Discount_Value]],"NOT FOUND") -> 17847.45 | V361: =IFERROR(RawSalesTable5[[#This Row],[Quantity]]*RawSalesTable5[[#This Row],[Unit_Cost]],"NOT FOUND") -> 14700 | W361: =IFERROR(RawSalesTable5[[#This Row],[Net_Revenue]]-RawSalesTable5[[#This Row],[Cost]],"NOT FOUND") -> 3147.45 | X361: =IF(RawSalesTable5[[#This Row],[Lookup_Status]]="Missing Product","",IFERROR(RawSalesTable5[[#This Row],[Profit]]/RawSalesTable5[[#This Row],[Net_Revenue]],0)) -> 0.17635292 | Y361: =RawSalesTable5[[#This Row],[Ship_Date]]-RawSalesTable5[[#This Row],[Order_Date]] -> 3 | Z361: =DATE(YEAR(RawSalesTable5[[#This Row],[Order_Date]]),MONTH(RawSalesTable5[[#This Row],[Order_Date]]),1) -> 45870 | AA361: {=IF(RawSalesTable5[[#This Row],[Lookup_Status]]="Missing Product","",_xlfn.IFS(RawSalesTable5[[#This Row],[Net_Revenue]]>=20000,"High",RawSalesTable5[[#This Row],[Net_Revenue]]>=10000,"Medium",TRUE,"Low"))} -> Medium

Sheet Raw_Sales
A1: Order_ID | B1: Order_Date | C1: Ship_Date | D1: City | E1: Salesperson | F1: Product_Code | G1: Sales_Channel | H1: Customer_Segment | I1: Quantity | J1: Discount_Pct | K1: Payment_Mode | L1: Returned | M1: Customer_Rating
A2: ORD-5001 | B2: 45792 | C2: 45794 | D2: Delhi | E2: Ananya | F2: P109 | G2: Corporate | H2: Small Business | I2: 2 | J2: 0 | K2: Cash on Delivery | L2: No | M2: 4
A3: ORD-5002 | B3: 45985 | C3: 45987 | D3: NOIDA | E3: Rohan | F3: P106 | G3: Website | H3: Small Business | I3: 2 | J3: 0 | K3: Net Banking | L3: No | M3: 3
A4: ORD-5003 | B4: 45782 | C4: 45783 | D4: MATHURA | E4: Meera | F4: P106 | G4: Website | H4: Corporate | I4: 1 | J4: 0 | K4: Cash on Delivery | L4: No | M4: 3
A5: ORD-5004 | B5: 45851 | C5: 45858 | D5: Gurgaon | E5: Vikram | F5: P108 | G5: Corporate | H5: Consumer | I5: 2 | J5: 0.05 | K5: Cash on Delivery | L5: No | M5: 4
A6: ORD-5005 | B6: 45838 | C6: 45843 | D6: faridabad | E6: Sana | F6: P111 | G6: Marketplace | H6: Consumer | I6: 1 | J6: 0.2 | K6: Net Banking | L6: No | M6: 5
A7: ORD-5006 | B7: 45964 | C7: 45972 | D7: delhi | E7: Arjun | F7: P106 | G7: Website | H7: Small Business | I7: 4 | J7: 0.1 | K7: Credit Card | L7: No | M7: 4
A8: ORD-5007 | B8: 45812 | C8: 45816 | D8: Noida | E8: Ananya | F8: P104 | G8: Corporate | H8: Consumer | I8: 5 | J8: 0 | K8: credit card | L8: No | M8: 3
A9: ORD-5008 | B9: 46020 | C9: 46024 | D9: MATHURA | E9: Rohan | F9: P102 | G9: Marketplace | H9: Corporate | I9: 5 | J9: 0 | K9: Debit Card | L9: No | M9: 5
A10: ORD-5009 | B10: 45829 | C10: 45832 | D10: Gurgaon | E10: Meera | F10: P103 | G10: Marketplace | H10: Small Business | I10: 3 | J10: 0.1 | K10: credit card | L10: No | M10: 4
A11: ORD-5010 | B11: 45778 | C11: 45786 | D11: Faridabad | E11: Vikram | F11: P101 | G11: Retail Store | H11: Small Business | I11: 3 | J11: 0.2 | K11: Credit Card | L11: Yes | M11: 1
A12: ORD-5011 | B12: 45695 | C12: 45699 | D12: New Delhi | E12: Sana | F12: P104 | G12: Website | H12: Small Business | I12: 2 | J12: 0.1 | K12: Credit Card | L12: No | M12: 5
A13: ORD-5012 | B13: 46006 | C13: 46014 | D13: noida | E13: Arjun | F13: P102 | G13: Corporate | H13: Consumer | I13: 5 | J13: 0.1 | K13: Cash on Delivery | L13: No | M13: 5
... A20: ORD-5019 | B20: 45959 | C20: 45964 | D20: Gurgaon | E20: Ananya | F20: P105 | G20: Website | H20: Small Business | I20: 2 | J20: 0 | K20: upi | L20: No | M20: 3
A21: ORD-5020 | B21: 46013 | C21: 46014 | E21: Rohan | F21: P104 | G21: Retail Store | H21: Corporate | I21: 2 | J21: 0.15 | K21: Credit Card | L21: Yes | M21: 1
A22: ORD-5021 | B22: 45714 | C22: 45720 | D22: DELHI | E22: Meera | F22: P110 | G22: Marketplace | H22: Consumer | I22: 1 | J22: 0.1 | K22: credit card | L22: No | M22: 4
A23: ORD-5022 | B23: 45783 | C23: 45784 | D23: NOIDA | E23: Vikram | F23: P112 | G23: Corporate | H23: Corporate | I23: 5 | J23: 0.1 | K23: credit card | L23: No | M23: 3
A24: ORD-5023 | B24: 45851 | C24: 45855 | D24: MATHURA | E24: Sana | F24: P102 | G24: Corporate | H24: Small Business | I24: 2 | J24: 0 | K24: Debit Card | L24: No | M24: 5
A25: ORD-5024 | B25: 45828 | C25: 45831 | D25: GURUGRAM | E25: Arjun | F25: P104 | G25: Corporate | H25: Corporate | I25: 1 | J25: 0 | K25: Net Banking | L25: No | M25: 5
A26: ORD-5025 | B26: 45702 | C26: 45710 | D26: faridabad | E26: Ananya | F26: P110 | G26: Website | H26: Corporate | I26: 1 | J26: 0.15 | K26: COD | L26: No | M26: 4
A27: ORD-5026 | B27: 45802 | C27: 45808 | D27: Delhi | E27: Rohan | F27: P107 | G27: Corporate | H27: Small Business | I27: 4 | J27: 0.2 | K27: Debit Card | L27: No | M27: 5
A28: ORD-5027 | B28: 46010 | C28: 46012 | D28: Noida | E28: Meera | F28: P102 | G28: Corporate | H28: Small Business | I28: 4 | J28: 0.15 | K28: UPI | L28: No | M28: 3
A29: ORD-5028 | B29: 45947 | C29: 45952 | D29: Mathura | E29: Vikram | F29: P112 | G29: Website | H29: Consumer | I29: 1 | J29: 0 | K29: upi | L29: No | M29: 5
A30: ORD-5029 | B30: 45845 | C30: 45849 | D30: Gurgaon | E30: Sana | F30: P106 | G30: Retail Store | H30: Corporate | I30: 2 | J30: 0.2 | K30: Debit Card | L30: No | M30: 4
A31: ORD-5030 | B31: 45754 | C31: 45761 | D31: faridabad | E31: Arjun | F31: P112 | G31: Corporate | H31: Consumer | I31: 5 | J31: 0 | K31: COD | L31: No | M31: 5
A32: ORD-5031 | B32: 45974 | C32: 45982 | D32: DELHI | E32: Ananya | F32: P102 | G32: Marketplace | H32: Consumer | I32: 4 | J32: 0.2 | K32: COD | L32: No | M32: 4
A33: ORD-5032 | B33: 45899 | C33: 45905 | D33: noida | E33: Rohan | F33: P112 | G33: Marketplace | H33: Small Business | I33: 5 | J33: 0 | K33: COD | L33: No | M33: 5
... A75: ORD-5074 | B75: 45848 | C75: 45850 | D75: gurugram | E75: Rohan | F75: P101 | G75: Website | H75: Consumer | I75: 5 | J75: 0.1 | K75: upi | L75: No | M75: 4
A76: ORD-5075 | B76: 45721 | C76: 45728 | E76: Meera | F76: P109 | G76: Retail Store | H76: Consumer | I76: 4 | J76: 0.1 | K76: COD | L76: Yes | M76: 1
A77: ORD-5076 | B77: 45969 | C77: 45974 | D77: Delhi | E77: Vikram | F77: P105 | G77: Retail Store | H77: Small Business | I77: 4 | J77: 0 | K77: upi | L77: No | M77: 5
A78: ORD-5077 | B78: 45930 | C78: 45932 | D78: Noida | E78: Sana | F78: P112 | G78: Marketplace | H78: Corporate | I78: 1 | J78: 0.1 | K78: Net Banking | L78: No | M78: 5
A79: ORD-5078 | B79: 45766 | C79: 45773 | D79: MATHURA | E79: Arjun | F79: P104 | G79: Retail Store | H79: Consumer | I79: 3 | J79: 0.1 | K79: Net Banking | L79: No | M79: 3
A80: ORD-5079 | B80: 45791 | C80: 45795 | D80: Gurugram | E80: Ananya | F80: P111 | G80: Corporate | H80: Corporate | I80: 1 | J80: 0.1 | K80: Net Banking | L80: Yes | M80: 1
A81: ORD-5080 | B81: 45814 | C81: 45816 | D81: faridabad | E81: Rohan | F81: P106 | G81: Corporate | H81: Corporate | I81: 5 | J81: 0.05 | K81: Credit Card | L81: No | M81: 3
A82: ORD-5081 | B82: 45760 | C82: 45762 | D82: New Delhi | E82: Meera | F82: P103 | G82: Retail Store | H82: Small Business | I82: 5 | J82: 0 | K82: Cash on Delivery | L82: No | M82: 3
A83: ORD-5082 | B83: 45798 | C83: 45801 | D83: Noida | E83: Vikram | F83: P109 | G83: Marketplace | H83: Consumer | I83: 3 | J83: 0 | K83: upi | L83: No | M83: 4
A84: ORD-5083 | B84: 45689 | C84: 45696 | D84: Mathura | E84: Sana | F84: P101 | G84: Corporate | H84: Small Business | I84: 5 | J84: 0.15 | K84: Net Banking | L84: No | M84: 4
A85: ORD-5084 | B85: 45925 | C85: 45932 | D85: GURUGRAM | E85: Arjun | F85: P103 | G85: Website | H85: Consumer | I85: 4 | J85: 0 | K85: COD | L85: No | M85: 4
A86: ORD-5085 | B86: 45967 | C86: 45975 | D86: FARIDABAD | E86: Ananya | F86: P105 | G86: Retail Store | H86: Consumer | I86: 2 | J86: 0 | K86: UPI | L86: No | M86: 4
A87: ORD-5086 | B87: 45772 | C87: 45777 | D87: Delhi | E87: Rohan | F87: P107 | G87: Marketplace | H87: Consumer | I87: 2 | J87: 0.1 | K87: Debit Card | L87: No | M87: 5
...

Sheet Pivot_Analysis
A1: Row Labels | B1: Sum of Net_Revenue | C1: Sum of Profit | E1: Row Labels | F1: Sum of Net_Revenue | G1: Sum of Profit | I1: Row Labels | J1: Sum of Net_Revenue | K1: Sum of Profit | M1: Row Labels | N1: Sum of Net_Revenue | O1: Sum of Profit | Q1: Row Labels | R1: Sum of Net_Revenue | S1: Sum of Profit
A2: 45658 | B2: 347480.45 | C2: 102260.45 | E2: Delhi | F2: 833653.8 | G2: 237983.8 | I2: Accessories | J2: 835809.05 | K2: 328119.05 | M2: Corporate | N2: 1020686.2 | O2: 297116.25 | Q2: Ananya | R2: 743898.05 | S2: 194048.05
A3: 45689 | B3: 227343.75 | C3: 67583.75 | E3: Faridabad | F3: 1028136.2 | G3: 282666.25 | I3: Audio | J3: 441031.9 | K3: 153181.9 | M3: Marketplace | N3: 952633.3 | O3: 256143.3 | Q3: Arjun | R3: 623600.85 | S3: 171100.85
A4: 45717 | B4: 398596 | C4: 105396 | E4: Gurugram | F4: 706352.1 | G4: 197342.1 | I4: Displays | J4: 879382.35 | K4: 196882.35 | M4: Retail Store | N4: 1009244.5 | O4: 297964.5 | Q4: Meera | R4: 713308.7 | S4: 193018.7
A5: 45748 | B5: 397527.6 | C5: 106417.6 | E5: Mathura | F5: 674139.95 | G5: 190179.95 | I5: Furniture | J5: 1050341.9 | K5: 269241.95 | M5: Website | N5: 1199698.2 | O5: 318998.2 | Q5: Rohan | R5: 707121.85 | S5: 215411.85
A6: 45778 | B6: 366911.05 | C6: 118641.05 | E6: Noida | F6: 799625.05 | G6: 228725.05 | I6: Storage | J6: 975697 | K6: 222797 | M6: Grand Total | N6: 4182262.2 | O6: 1170222.2 | Q6: Sana | R6: 765844.6 | S6: 206614.6
A7: 45809 | B7: 318411.2 | C7: 94751.2 | E7: Unknown | F7: 140355.1 | G7: 33325.1 | I7: Grand Total | J7: 4182262.2 | K7: 1170222.2 | Q7: Vikram | R7: 628488.2 | S7: 190028.2
A8: 45839 | B8: 273176.4 | C8: 74026.4 | E8: Grand Total | F8: 4182262.2 | G8: 1170222.3 | Q8: Grand Total | R8: 4182262.2 | S8: 1170222.2
A9: 45870 | B9: 426069.2 | C9: 104249.2
A10: 45901 | B10: 510108.75 | C10: 138588.75
A11: 45931 | B11: 320910.3 | C11: 83590.3
A12: 45962 | B12: 395578.5 | C12: 120018.5
A13: 45992 | B13: 200149.05 | C13: 54699.05
A14: Grand Total | B14: 4182262.2 | C14: 1170222.2

Sheet Sales_Targets
A1: Monthly Salesperson Targets | D1: Salesperson Vs Target
A3: Salesperson | B3: Monthly_Revenue_Target | C3: Monthly_Profit_Target | D3: Salesperson | E3: Actual Monthly Revenue | F3: Monthly Revenue Target
A4: Ananya | B4: 420000 | C4: 95000 | D4: =A4 -> Ananya | E4: =_xlfn.XLOOKUP(D4,Pivot_Analysis!$Q$2:$Q$7,Pivot_Analysis!$R$2:$R$7,0)/12 -> 61991.504 | F4: =_xlfn.XLOOKUP(D4,$A$4:$A$9,$B$4:$B$9,0) -> 420000
A5: Rohan | B5: 445000 | C5: 102000 | D5: =A5 -> Rohan | E5: =_xlfn.XLOOKUP(D5,Pivot_Analysis!$Q$2:$Q$7,Pivot_Analysis!$R$2:$R$7,0)/12 -> 58926.821 | F5: =_xlfn.XLOOKUP(D5,$A$4:$A$9,$B$4:$B$9,0) -> 445000
A6: Meera | B6: 470000 | C6: 109000 | D6: =A6 -> Meera | E6: =_xlfn.XLOOKUP(D6,Pivot_Analysis!$Q$2:$Q$7,Pivot_Analysis!$R$2:$R$7,0)/12 -> 59442.392 | F6: =_xlfn.XLOOKUP(D6,$A$4:$A$9,$B$4:$B$9,0) -> 470000
A7: Vikram | B7: 495000 | C7: 116000 | D7: =A7 -> Vikram | E7: =_xlfn.XLOOKUP(D7,Pivot_Analysis!$Q$2:$Q$7,Pivot_Analysis!$R$2:$R$7,0)/12 -> 52374.017 | F7: =_xlfn.XLOOKUP(D7,$A$4:$A$9,$B$4:$B$9,0) -> 495000
A8: Sana | B8: 520000 | C8: 123000 | D8: =A8 -> Sana | E8: =_xlfn.XLOOKUP(D8,Pivot_Analysis!$Q$2:$Q$7,Pivot_Analysis!$R$2:$R$7,0)/12 -> 63820.383 | F8: =_xlfn.XLOOKUP(D8,$A$4:$A$9,$B$4:$B$9,0) -> 520000
A9: Arjun | B9: 545000 | C9: 130000 | D9: =A9 -> Arjun | E9: =_xlfn.XLOOKUP(D9,Pivot_Analysis!$Q$2:$Q$7,Pivot_Analysis!$R$2:$R$7,0)/12 -> 51966.737 | F9: =_xlfn.XLOOKUP(D9,$A$4:$A$9,$B$4:$B$9,0) -> 545000

Sheet Dashboard_Canvas
A1: E-commerce Sales & Profitability Dashboard
A4: Net Revenue | D4: Profit | G4: Profit Margin | J4: Orders | M4: Return Rate
A5: =Pivot_Analysis!B14 -> 4182262.2 | D5: =Pivot_Analysis!C14 -> 1170222.2 | G5: =IFERROR(D5/A5,0) -> 0.27980604 | J5: =COUNTA(RawSalesTable5[Order_ID]) -> 360 | M5: =COUNTIF(RawSalesTable5[Returned],"Yes")/COUNTA(RawSalesTable5[Order_ID]) -> 0.069444444
A37: Three recommendations
A38: 1. Investigate order volume, discounts, returns and product mix in February and December, then plan targeted promotions or inventory adjustments.
A39: 2. Reset salesperson targets using historical monthly performance and introduce achievable staged milestones with coaching.
A40: 3. Replicate the product and channel practices driving Faridabad and Accessories while correcting Unknown city records before making geographic decisions.
A41: Findings
A42: 1. September generated the highest monthly net revenue (₹510,109) and profit (₹138,589).
A43: 2. December generated the lowest monthly profit (₹54,699), followed by February (₹67,584).
A44: 3. Accessories generated the highest category profit (₹328,119), while Furniture generated the highest category revenue (₹1,050,342).
A45: 4. Faridabad was the strongest city, producing ₹1,028,136 in net revenue and ₹282,666 in profit.
A46: 5. None of the six salespersons met the monthly revenue target; achievement ranged from 9.5% for Arjun to 14.8% for Ananya.

Sheet Product_Lookup
A1: Product Lookup — use this table for XLOOKUP
A3: Product_Code | B3: Product_Name | C3: Category | D3: Unit_Price | E3: Unit_Cost
A4: P101 | B4: Wireless Mouse | C4: Accessories | D4: 799 | E4: 420
A5: P102 | B5: Mechanical Keyboard | C5: Accessories | D5: 2499 | E5: 1450
A6: P103 | B6: HD Webcam | C6: Accessories | D6: 2899 | E6: 1700
A7: P104 | B7: USB-C Hub | C7: Accessories | D7: 1599 | E7: 870
A8: P105 | B8: 24-inch Monitor | C8: Displays | D8: 12999 | E8: 9100
A9: P106 | B9: Wireless Headset | C9: Audio | D9: 3499 | E9: 2100
A10: P107 | B10: Laptop Stand | C10: Accessories | D10: 1899 | E10: 980
A11: P108 | B11: SSD 1TB | C11: Storage | D11: 6999 | E11: 4900
A12: P109 | B12: Ergonomic Chair | C12: Furniture | D12: 10499 | E12: 7600
A13: P110 | B13: LED Desk Lamp | C13: Furniture | D13: 1999 | E13: 1050
A14: P111 | B14: Bluetooth Speaker | C14: Audio | D14: 2799 | E14: 1650
A15: P112 | B15: Portable HDD 2TB | C15: Storage | D15: 5899 | E15: 4100

Sheet Work_Log
A1: Project Work Log
A3: Date | B3: Task | C3: Done alone? | D3: Help used | E3: Decision/check | F3: What I learned
A4: 24/8/26 | B4: Data cleaning, lookups and calculated columns | C4: With guidance | D4: Excel documentation | E4: Validated calculations and data quality | F4: Learned how I can clean and analyze big data in very short amount of time and certain calculations and how xlookup is more useful than vlookup
A5: 25/8/26 | B5: PivotTables, KPIs, charts and insights | C5: With guidance | D5: Excel documentation | E5: Validated calculations and data quality | F5: Learned difference b/w kpi and pivot table and how different graphs affect understanding as a viewer
